TODO's for migration to 4.2

- set versioning-policies through GS - DONE
- RecensioLanguageSelector fixen - DONE
- login fixen - DONE
- kommentare fixen - DONE
- suche anpassen (@@search statt search, auch erweiterte Suche, einschränkungen-dropdown auch für anonymous testen, recensio.theme/recensio/theme/skins/recensio_theme/search.pt fixen) - DONE
- Reste von cdv rausnemhen (z.B. default.xml in skins) - DONE
- schauen was mit collective.solr zu machen ist (old: collective.solr-3.0a2 update auf 3.0 oder nicht?) - DONE

Schritte zur Durchführung der Migration auf dem testserver:

- solr-instance, zeo und worker im fg starten: http://recensio.syslab.com:8099

- solr-instance muss auf 8984 laufen oder in http://recensio.syslab.com:8099/recensio/@@solr-controlpanel auf 4084 gesetzt werden (kann nciht speichern)
- solr-instace wird auf 195.62.125.219 erwartet: auf dem testserver auf 176.9.59.108 oder localhost umstellen (kann nicht speichern)

- try: delete /Members/Hans_Mustermann in ZMI (won't help)
- try: delete user "Hans Musterman" http://recensio.syslab.com:8099/recensio/@@usergroup-userprefs (won't help)
- try: update uid_catalog (not working)
- try: reindex index UID in portal_catalog ()
- try: reinstall collective.solr (kann jetzt Einträge in solr-controlpanel speichern!)

- Plone migrieren
  http://recensio.syslab.com:8099/recensio/@@plone-upgrade
  falls lokal: BDPDebugMode raus und entweder blobs rein oder experimental.gracefulblobmissing drin haben
  dauert ca 1h (Wartezeit nach xxx INFO plone.app.upgrade Ran upgrade step: Add Site Administrator role)

- Alle dann noch verfügbaren upgrade-steps laufen lassen

- Produkte deinstalliern:
  xdv-theme deaktivieren in plone_control_panel
  XDV theme support (collective.xdv) deinstallieren

- Upgrade-Steps:
  Alle verfügbaren Upgrade-steps durchführen außer jquery und jquerytools.

- Produkte reinstallieren:
  alle veralteten externen
  recensio.policy (zieht den rest)

- "Recensio Theme" reinstallieren migriert das design nach Diazo.
   Einstellung von "XDV theme support" auf "Diazo theme" übertragen? Nicht nötig!

- Solr reindizieren:
  /@@solr-maintenance/clear und /@@solr-maintenance/reindex


Problem: solr-port wird durch recensio.policy geändert. Lösung: Wieder auf den gewünschten port setzen (z.B. 2084 auf recensio00-plone42).

Problem: classic_theme ist aktiv nach update von plonetheme.classic. (sieht man an authoring.css). Lösung: in portal_skins das skin auf sunburst wechseln.

Problem: Fehler im rechten Portlet. Lösung: Ignorieren, da es nur auftritt solange solr nicht reindiziert wurde.

Problem: supervisorctl findet keine conf (liegen in parts/supervisor/supervisord.conf)

Problem: buildout lädt recensio.policy nicht als src sondern als egg

2012-12-06 14:51:50 ERROR plone.app.upgrade Upgrade aborted. Error:
Traceback (most recent call last):
  File "/home/recensio/eggs/Products.CMFPlone-4.2.2-py2.7.egg/Products/CMFPlone/MigrationTool.py", line 178, in upgrade
    step['step'].doStep(setup)
  File "/home/recensio/eggs/Products.GenericSetup-1.7.3-py2.7.egg/Products/GenericSetup/upgrade.py", line 140, in doStep
    self.handler(tool)
  File "/home/recensio/eggs/plone.app.upgrade-1.2.2-py2.7.egg/plone/app/upgrade/v41/alphas.py", line 278, in to41alpha3
    optimize_indexes(context)
  File "/home/recensio/eggs/plone.app.upgrade-1.2.2-py2.7.egg/plone/app/upgrade/v41/alphas.py", line 271, in optimize_indexes
    convert_to_uuidindex(catalog, index)
  File "/home/recensio/eggs/plone.app.upgrade-1.2.2-py2.7.egg/plone/app/upgrade/v41/alphas.py", line 216, in convert_to_uuidindex
    'with multiple docids: %r' % (k, paths))
ValueError: Inconsistent UID index, UID 512298481d7f251d65f07ba0877ada1b is associated with multiple docids: {('', 'recensio', 'Members', 'Hans_Mustermann', 'mustermonographie', '++conversation++default', '1294837415513892'): 1973786748, ('', 'recensio', 'Members', 'Hans_Mustermann', 'mustermonographie', '++conversation++default', '1294667619629594'): 1973786601}



Notizen:
catalog clear und migrate dauert mit und ohne blobs ewig. Speedup?
Sentry deaktivieren?

Fehler beim upgrade:

2012-10-30 16:56:07 INFO plone.app.upgrade Converting index `UID` to UUIDIndex.


2012-10-30 16:56:08 ERROR sentry.errors Unable to reach Sentry log server: HTTP Error 403: FORBIDDEN (url: https://app.getsentry.com/api/store/, body: Creation of this event was blocked)
Traceback (most recent call last):
  File "/home/recensio/eggs/raven-2.0.6-py2.7.egg/raven/base.py", line 432, in send_remote
    self._send_remote(url=url, data=data, headers=headers)
  File "/home/recensio/eggs/raven-2.0.6-py2.7.egg/raven/base.py", line 406, in _send_remote
    return transport.send(data, headers)
  File "/home/recensio/eggs/raven-2.0.6-py2.7.egg/raven/transport/base.py", line 144, in send
    response = urllib2.urlopen(req, data, self.timeout).read()
  File "/usr/lib/python2.7/urllib2.py", line 126, in urlopen
    return _opener.open(url, data, timeout)
  File "/usr/lib/python2.7/urllib2.py", line 406, in open
    response = meth(req, response)
  File "/usr/lib/python2.7/urllib2.py", line 519, in http_response
    'http', request, response, code, msg, hdrs)
  File "/usr/lib/python2.7/urllib2.py", line 444, in error
    return self._call_chain(*args)
  File "/usr/lib/python2.7/urllib2.py", line 378, in _call_chain
    result = func(*args)
  File "/usr/lib/python2.7/urllib2.py", line 527, in http_error_default
    raise HTTPError(req.get_full_url(), code, msg, hdrs, fp)
HTTPError: HTTP Error 403: FORBIDDEN



Traceback (most recent call last):
  File "/home/recensio/eggs/Products.CMFPlone-4.2.2-py2.7.egg/Products/CMFPlone/MigrationTool.py", line 178, in upgrade
    step['step'].doStep(setup)
  File "/home/recensio/eggs/Products.GenericSetup-1.7.3-py2.7.egg/Products/GenericSetup/upgrade.py", line 140, in doStep
    self.handler(tool)
  File "/home/recensio/eggs/plone.app.upgrade-1.2.2-py2.7.egg/plone/app/upgrade/v41/alphas.py", line 278, in to41alpha3
    optimize_indexes(context)
  File "/home/recensio/eggs/plone.app.upgrade-1.2.2-py2.7.egg/plone/app/upgrade/v41/alphas.py", line 271, in optimize_indexes
    convert_to_uuidindex(catalog, index)
  File "/home/recensio/eggs/plone.app.upgrade-1.2.2-py2.7.egg/plone/app/upgrade/v41/alphas.py", line 216, in convert_to_uuidindex
    'with multiple docids: %r' % (k, paths))
ValueError: Inconsistent UID index, UID 512298481d7f251d65f07ba0877ada1b is associated with multiple docids: {('', 'recensio', 'Members', 'Hans_Mustermann', 'mustermonographie', '++conversation++default', '1294837415513892'): 1973786748, ('', 'recensio', 'Members', 'Hans_Mustermann', 'mustermonographie', '++conversation++default', '1294667619629594'): 1973786601}


2012-10-30 16:56:07 ERROR plone.app.upgrade Upgrade aborted. Error:
Traceback (most recent call last):
  File "/home/recensio/eggs/Products.CMFPlone-4.2.2-py2.7.egg/Products/CMFPlone/MigrationTool.py", line 178, in upgrade
    step['step'].doStep(setup)
  File "/home/recensio/eggs/Products.GenericSetup-1.7.3-py2.7.egg/Products/GenericSetup/upgrade.py", line 140, in doStep
    self.handler(tool)
  File "/home/recensio/eggs/plone.app.upgrade-1.2.2-py2.7.egg/plone/app/upgrade/v41/alphas.py", line 278, in to41alpha3
    optimize_indexes(context)
  File "/home/recensio/eggs/plone.app.upgrade-1.2.2-py2.7.egg/plone/app/upgrade/v41/alphas.py", line 271, in optimize_indexes
    convert_to_uuidindex(catalog, index)
  File "/home/recensio/eggs/plone.app.upgrade-1.2.2-py2.7.egg/plone/app/upgrade/v41/alphas.py", line 216, in convert_to_uuidindex
    'with multiple docids: %r' % (k, paths))
ValueError: Inconsistent UID index, UID 512298481d7f251d65f07ba0877ada1b is associated with multiple docids: {('', 'recensio', 'Members', 'Hans_Mustermann', 'mustermonographie', '++conversation++default', '1294837415513892'): 1973786748, ('', 'recensio', 'Members', 'Hans_Mustermann', 'mustermonographie', '++conversation++default', '1294667619629594'): 1973786601}


2012-10-30 17:30:22 ERROR collective.solr.indexer Error occured while getting data for indexing!
Traceback (most recent call last):
  File "/home/recensio/eggs/collective.solr-3.0a2-py2.7.egg/collective/solr/indexer.py", line 214, in getData
    value = value()
  File "/home/recensio/recensio01-plone42/src/recensio.contenttypes/recensio/contenttypes/content/review.py", line 432, in SearchableText
    value = " ".join([data, comment.getText().encode('utf8')])
UnicodeDecodeError: 'ascii' codec can't decode byte 0xc3 in position 64: ordinal not in range(128)
2012-10-30 17:30:42 ERROR collective.solr.indexer Error occured while getting data for indexing!
Traceback (most recent call last):
  File "/home/recensio/eggs/collective.solr-3.0a2-py2.7.egg/collective/solr/indexer.py", line 214, in getData
    value = value()
  File "/home/recensio/recensio01-plone42/src/recensio.contenttypes/recensio/contenttypes/content/review.py", line 432, in SearchableText
    value = " ".join([data, comment.getText().encode('utf8')])
UnicodeDecodeError: 'ascii' codec can't decode byte 0xc3 in position 44: ordinal not in range(128)

This went away after deleting /Members/Hans_Mustermann

Fehler bei comments:

2012-11-02 12:13:10 ERROR Zope.SiteErrorLog 1351854790.710.620149978471 http://localhost:8081/recensio/Members/gerken/test-1/review_view
Traceback (innermost last):
  Module ZPublisher.Publish, line 126, in publish
  Module ZPublisher.mapply, line 77, in mapply
  Module ZPublisher.Publish, line 46, in call_object
  Module recensio.contenttypes.browser.review, line 286, in __call__
  Module Products.Five.browser.pagetemplatefile, line 125, in __call__
  Module Products.Five.browser.pagetemplatefile, line 59, in __call__
  Module zope.pagetemplate.pagetemplate, line 113, in pt_render
   - Warning: Macro expansion failed
   - Warning: <type 'exceptions.NameError'>: name 'field_name' is not defined
  Module zope.tal.talinterpreter, line 271, in __call__
  Module zope.tal.talinterpreter, line 343, in interpret
  Module zope.tal.talinterpreter, line 888, in do_useMacro
  Module zope.tal.talinterpreter, line 343, in interpret
  Module zope.tal.talinterpreter, line 533, in do_optTag_tal
  Module zope.tal.talinterpreter, line 518, in do_optTag
  Module zope.tal.talinterpreter, line 513, in no_tag
  Module zope.tal.talinterpreter, line 343, in interpret
  Module zope.tal.talinterpreter, line 852, in do_condition
  Module zope.tal.talinterpreter, line 343, in interpret
  Module zope.tal.talinterpreter, line 742, in do_insertStructure_tal
  Module Products.PageTemplates.Expressions, line 218, in evaluateStructure
  Module zope.tales.tales, line 696, in evaluate
   - URL: file:/Users/philip/.cache/buildout/eggs/plonetheme.sunburst-1.2.7-py2.7.egg/plonetheme/sunburst/skins/sunburst_templates/main_template.pt
   - Line 134, Column 12
   - Expression: <StringExpr u'plone.belowcontent'>
   - Names:
      {'args': (),
       'container': <PresentationOnlineResource at /recensio/Members/gerken/test-1>,
       'context': <PresentationOnlineResource at /recensio/Members/gerken/test-1>,
       'default': <object object at 0x10d1e4b70>,
       'here': <PresentationOnlineResource at /recensio/Members/gerken/test-1>,
       'loop': {},
       'nothing': None,
       'options': {},
       'repeat': <Products.PageTemplates.Expressions.SafeMapping object at 0x115f65c58>,
       'request': <HTTPRequest, URL=http://localhost:8081/recensio/Members/gerken/test-1/review_view>,
       'root': <Application at >,
       'template': <Products.Five.browser.pagetemplatefile.ViewPageTemplateFile object at 0x11117eb90>,
       'traverse_subpath': [],
       'user': <PropertiedUser 'rescue'>,
       'view': <Products.Five.metaclass.View object at 0x115e9ca90>,
       'views': <Products.Five.browser.pagetemplatefile.ViewMapper object at 0x115e9c6d0>}
  Module zope.contentprovider.tales, line 80, in __call__
  Module plone.app.viewletmanager.manager, line 154, in render
  Module plone.app.viewletmanager.manager, line 85, in render
  Module plone.app.layout.viewlets.common, line 48, in render
  Module Products.Five.browser.pagetemplatefile, line 125, in __call__
  Module Products.Five.browser.pagetemplatefile, line 59, in __call__
  Module zope.pagetemplate.pagetemplate, line 113, in pt_render
  Module zope.tal.talinterpreter, line 271, in __call__
  Module zope.tal.talinterpreter, line 343, in interpret
  Module zope.tal.talinterpreter, line 852, in do_condition
  Module zope.tal.talinterpreter, line 343, in interpret
  Module zope.tal.talinterpreter, line 533, in do_optTag_tal
  Module zope.tal.talinterpreter, line 518, in do_optTag
  Module zope.tal.talinterpreter, line 513, in no_tag
  Module zope.tal.talinterpreter, line 343, in interpret
  Module zope.tal.talinterpreter, line 533, in do_optTag_tal
  Module zope.tal.talinterpreter, line 518, in do_optTag
  Module zope.tal.talinterpreter, line 513, in no_tag
  Module zope.tal.talinterpreter, line 343, in interpret
  Module zope.tal.talinterpreter, line 852, in do_condition
  Module zope.tal.talinterpreter, line 343, in interpret
  Module zope.tal.talinterpreter, line 821, in do_loop_tal
  Module zope.tal.talinterpreter, line 343, in interpret
  Module zope.tal.talinterpreter, line 533, in do_optTag_tal
  Module zope.tal.talinterpreter, line 518, in do_optTag
  Module zope.tal.talinterpreter, line 513, in no_tag
  Module zope.tal.talinterpreter, line 343, in interpret
  Module zope.tal.talinterpreter, line 852, in do_condition
  Module zope.tal.talinterpreter, line 343, in interpret
  Module zope.tal.talinterpreter, line 531, in do_optTag_tal
  Module zope.tal.talinterpreter, line 513, in no_tag
  Module zope.tal.talinterpreter, line 343, in interpret
  Module zope.tal.talinterpreter, line 742, in do_insertStructure_tal
  Module Products.PageTemplates.Expressions, line 218, in evaluateStructure
  Module zope.tales.tales, line 696, in evaluate
   - URL: /Users/philip/workspace/recensio/src/recensio.policy/recensio/policy/browser/templates/comments.pt
   - Line 62, Column 20
   - Expression: <PythonExpr (view.cook(reply.getText()))>
   - Names:
      {'args': (),
       'container': <PresentationOnlineResource at /recensio/Members/gerken/test-1>,
       'context': <PresentationOnlineResource at /recensio/Members/gerken/test-1>,
       'default': <object object at 0x10d1e4b70>,
       'here': <PresentationOnlineResource at /recensio/Members/gerken/test-1>,
       'loop': {},
       'nothing': None,
       'options': {},
       'repeat': <Products.PageTemplates.Expressions.SafeMapping object at 0x115fae578>,
       'request': <HTTPRequest, URL=http://localhost:8081/recensio/Members/gerken/test-1/review_view>,
       'root': <Application at >,
       'template': <Products.Five.browser.pagetemplatefile.ViewPageTemplateFile object at 0x111624a50>,
       'traverse_subpath': [],
       'user': <PropertiedUser 'rescue'>,
       'view': <Products.Five.viewlet.metaconfigure.CommentsViewlet object at 0x11601f890>,
       'views': <Products.Five.browser.pagetemplatefile.ViewMapper object at 0x11601f990>}
  Module zope.tales.pythonexpr, line 59, in __call__
   - __traceback_info__: (view.cook(reply.getText()))
  Module <string>, line 1, in <module>
AttributeError: 'CommentsViewlet' object has no attribute 'cook'



xdv-config:

Domains:
beta.recensio.net
kielschwein:8010
localhost:8010
recensio.syslab.com
recensio00.fe.rzob.gocept.net
recensio:8010
www.recensio.net

Theme template:
python://recensio.theme/skins/recensio_theme/theme.html

Rules file:
python://recensio.theme/skins/recensio_theme/rules/default.xml

Unstyled paths:
^.*/.+/advanced/(source_editor|anchor)\.htm$
^.*/.+/plone(image|link)\.htm$
^.*/@@pageviewer
^.*/aq_parent(/.*)?$
^.*/emptypage$
^.*/error_log(/.*)?$
^.*/image_view_fullscreen$
^.*/manage$
^.*/manage_(?!translations_form)[^/]+$
^.*/manage_addProduct/.*$
^.*/plugins/searchreplace/searchreplace.htm$
^.*/plugins/table/(table|row|cell|merge_cells)\.htm$
^.*/portal_javascripts/.*/jscripts/tiny_mce/.*$
^.*/refbrowser_popup(\?.*)?$
^.*/tinymce-upload$
^.*popup$
^/googlead1fe7ef91f639f7.html$

Absolute URL prefix:
recensio
